#VRML_SIM R2019a utf8
WorldInfo {
}
Viewpoint {
  orientation -0.580303511597526 -0.812489061980966 0.055761622903837654 6.047745432373489
  position 0.7856167198433277 0.6021769877308983 1.560716740290043
}
TexturedBackground {
}
TexturedBackgroundLight {
}
Floor {
}
Solid {
  children [
    Group {
      children [
        DEF A Group {
          children [
            DEF P1 Transform {
              translation 0 0.48 -0.00259
              rotation 1 0 0 6.02
              children [
                Shape {
                  appearance DEF BASE PBRAppearance {
                    baseColor 0.9882352941176471 0.6862745098039216 0.24313725490196078
                    roughness 1
                    metalness 0
                  }
                  geometry DEF BOX1 Box {
                    size 0.1 1 0.05
                  }
                }
              ]
            }
            DEF P2 Transform {
              translation 0 0.48 -0.3
              rotation 1 0 0 0.262
              children [
                Shape {
                  appearance USE BASE
                  geometry USE BOX1
                }
              ]
            }
            DEF CYL_MEDIO Transform {
              translation 0 0.5 -0.155
              rotation 1 0 0 1.57
              children [
                DEF CYL_MEDIO Shape {
                  appearance USE BASE
                  geometry Cylinder {
                    height 0.275
                    radius 0.04
                  }
                }
              ]
            }
          ]
        }
        DEF COPY_A Transform {
          translation 1 0 0
          children [
            USE A
          ]
        }
        DEF BAR Transform {
          translation 0.5000000023015511 0.9800000004315412 -0.155
          rotation 0 0 1 1.5707963220000003
          children [
            Shape {
              appearance USE BASE
              geometry Cylinder {
                height 1.1
                radius 0.04
              }
            }
          ]
        }
        HingeJoint {
          jointParameters HingeJointParameters {
            axis 0 1 0
            anchor 0.5 0.9400000000000001 -0.155
          }
          endPoint Solid {
            translation 0.5004375822731715 0.92 -0.15475808730044477
            rotation 0 -1 0 2.07581684714679
            children [
              Shape {
                appearance PBRAppearance {
                  baseColor 0.9372549019607843 0.1607843137254902 0.1607843137254902
                  roughness 1
                  metalness 0
                }
                geometry Box {
                  size 0.2 0.05 0.05
                }
              }
            ]
            physics Physics {
            }
          }
        }
      ]
    }
  ]
}
